[2024-07-21T00:20:06.166+0000] {taskinstance.py:1159} INFO - Dependencies all met for dep_context=non-requeueable deps ti=<TaskInstance: our_dag_with_python_operator_v01.greet scheduled__2024-07-20T00:00:00+00:00 [queued]>
[2024-07-21T00:20:06.181+0000] {taskinstance.py:1159} INFO - Dependencies all met for dep_context=requeueable deps ti=<TaskInstance: our_dag_with_python_operator_v01.greet scheduled__2024-07-20T00:00:00+00:00 [queued]>
[2024-07-21T00:20:06.182+0000] {taskinstance.py:1361} INFO - Starting attempt 5 of 6
[2024-07-21T00:20:06.203+0000] {taskinstance.py:1382} INFO - Executing <Task(PythonOperator): greet> on 2024-07-20 00:00:00+00:00
[2024-07-21T00:20:06.209+0000] {standard_task_runner.py:57} INFO - Started process 27211 to run task
[2024-07-21T00:20:06.217+0000] {standard_task_runner.py:84} INFO - Running: ['***', 'tasks', 'run', 'our_dag_with_python_operator_v01', 'greet', 'scheduled__2024-07-20T00:00:00+00:00', '--job-id', '1098', '--raw', '--subdir', 'DAGS_FOLDER/create_dag_with_python_operator.py', '--cfg-path', '/tmp/tmpjyz4rbi9']
[2024-07-21T00:20:06.239+0000] {standard_task_runner.py:85} INFO - Job 1098: Subtask greet
[2024-07-21T00:20:06.298+0000] {task_command.py:416} INFO - Running <TaskInstance: our_dag_with_python_operator_v01.greet scheduled__2024-07-20T00:00:00+00:00 [running]> on host b8647d758ea8
[2024-07-21T00:20:06.449+0000] {taskinstance.py:1662} INFO - Exporting env vars: AIRFLOW_CTX_DAG_OWNER='Bowen' AIRFLOW_CTX_DAG_ID='our_dag_with_python_operator_v01' AIRFLOW_CTX_TASK_ID='greet' AIRFLOW_CTX_EXECUTION_DATE='2024-07-20T00:00:00+00:00' AIRFLOW_CTX_TRY_NUMBER='5' AIRFLOW_CTX_DAG_RUN_ID='scheduled__2024-07-20T00:00:00+00:00'
[2024-07-21T00:20:06.451+0000] {taskinstance.py:1937} ERROR - Task failed with exception
Traceback (most recent call last):
  File "/home/airflow/.local/lib/python3.8/site-packages/airflow/operators/python.py", line 192, in execute
    return_value = self.execute_callable()
  File "/home/airflow/.local/lib/python3.8/site-packages/airflow/operators/python.py", line 209, in execute_callable
    return self.python_callable(*self.op_args, **self.op_kwargs)
  File "/opt/airflow/dags/create_dag_with_python_operator.py", line 14, in greet
    first_name = ti.xcom_pull(task_id='get_name', key='first_name')
  File "/home/airflow/.local/lib/python3.8/site-packages/airflow/utils/session.py", line 79, in wrapper
    return func(*args, session=session, **kwargs)
TypeError: xcom_pull() got an unexpected keyword argument 'task_id'
[2024-07-21T00:20:06.467+0000] {taskinstance.py:1400} INFO - Marking task as UP_FOR_RETRY. dag_id=our_dag_with_python_operator_v01, task_id=greet, execution_date=20240720T000000, start_date=20240721T002006, end_date=20240721T002006
[2024-07-21T00:20:06.488+0000] {standard_task_runner.py:104} ERROR - Failed to execute job 1098 for task greet (xcom_pull() got an unexpected keyword argument 'task_id'; 27211)
[2024-07-21T00:20:06.541+0000] {local_task_job_runner.py:228} INFO - Task exited with return code 1
[2024-07-21T00:20:06.569+0000] {taskinstance.py:2778} INFO - 0 downstream tasks scheduled from follow-on schedule check
